Workbook

Sheet 급여테이블(변경전)
A1: 가상시 민원상담콜센터 직무GROUP 인력운영 기준
A4: Ⅰ. 관리 | S4: [ 담당PM : 홍길동 ]
A6: 요청조직명 | D6: 가상사업본부 가상사업단 가상1팀 | H6: 요청일자 | K6: 46023
A7: 요청사유 | D7: 2026년 최저임금 반영 | H7: 관리번호 | K7: 가상시 민원상담콜센터/2026년1월
A9: Ⅱ. 직무Group
A11: 직군명 | D11: TM직군
A12: 직무Group명 | D12: 가상시 민원상담콜센터 | H12: 직무Group정의 | K12: 고객상담
A14: Ⅲ. 직무 | R14: (단위 : 원, 명)
A15: 구분 | B15: 직무명 | E15: 직무정의 | H15: 직무/직책수당 | I15: 직무규정(소속) | R15: 비평가시 / (등급) | S15: 정원
A16: 조직장 | B16: 센터장 | E16: 센터장 업무 | H16: =Q67 -> 400000 | R16: X | S16: 1
B17: 팀장 | E17: 팀장 업무 | H17: =D67 -> 200000 | R17: X | S17: 1
B18: 교육/QAA | E18: 교육/QAA 업무 | H18: =E67 -> 150000 | R18: X | S18: 1
A19: 조직원 | B19: 상담사 | E19: 상담사 업무 | R19: X | S19: 20
A22: 계 | S22: =SUM(S16:S21) -> 23
A24: Ⅳ. 정원 | R24: (단위 : 명)
A25: 구분 | B25: 직급 | D25: 컨설턴트(일반) | I25: 컨설턴트(전문) | S25: 계
B26: 호봉 | D26: 수습 | E26: 상담1 | F26: 상담2 | G26: 상담3
A27: 정원 | D27: 3 | E27: 8 | F27: 6 | G27: 3 | S27: =SUM(D27:R27) -> 20
A28: 구분 | B28: 직급 | D28: Staff | P28: Leader | S28: 계
B29: 호봉 | D29: 상담팀장 | E29: 교육강사 | R29: 센터장
A30: 정원 | D30: 2 | E30: 1 | R30: 1 | S30: =SUM(D30:R30) -> 4
P31: 총계 | S31: =S27+S30 -> 24
A32: Ⅴ. 보수테이블 | R32: (단위 : 원, 명)
A33: 구분 | D33: 상담 | S33: 비고
D34: 수습 | E34: 상담1 | F34: 상담2 | G34: 상담3
A35: 기본급 | D35: =10320*209 -> 2156880 | E35: =10320*209 -> 2156880 | F35: =10320*209 -> 2156880 | G35: =10320*209 -> 2156880
A36: 직책수당
A37: 직무수당
A38: 근속수당 | F38: 20000 | G38: 40000
A39: 급식비 | D39: 90000 | E39: 90000 | F39: 90000 | G39: 90000
A40: 통근비
A41: 통상임금소계 | D41: =SUM(D35:D40) -> 2246880 | E41: =SUM(E35:E40) -> 2246880 | F41: =SUM(F35:F40) -> 2266880 | G41: =SUM(G35:G40) -> 2286880 | H41: =SUM(H35:H40) -> 0 | I41: =SUM(I35:I40) -> 0 | J41: =SUM(J35:J40) -> 0 | K41: =SUM(K35:K40) -> 0 | ... R41: =SUM(R35:R40) -> 0
A42: 업적수당 | C42: S | D42: 120000 | E42: 120000 | F42: 120000 | G42: 120000 | S42: 평가결과에 따름
C43: A | D43: 90000 | E43: 90000 | F43: 90000 | G43: 90000
C44: B | D44: 60000 | E44: 60000 | F44: 60000 | G44: 60000
C45: C. | D45: 30000 | E45: 30000 | F45: 30000 | G45: 30000
C46: D | D46: 10000 | E46: 10000 | F46: 10000 | G46: 10000
C47: E | D47: 0 | E47: 0 | F47: 0 | G47: 0 | H47: 0 | I47: 0 | J47: 0 | K47: 0 | L47: 0 | M47: 0 | N47: 0 | O47: 0 | P47: 0 | Q47: 0 | R47: 0
A48: 초과근무수당 | E48: =ROUNDUP(E53*2,-1) -> 32260 | F48: =ROUNDUP(F53*2,-1) -> 32540 | G48: =ROUNDUP(G53*2,-1) -> 32830 | S48: 2H
A49: 야간근로수당
...

Sheet 급여테이블(변경후)
A1: 가상시 민원상담콜센터 직무GROUP 인력운영 기준
A4: Ⅰ. 관리 | S4: [ 담당PM : 홍길동 ]
A6: 요청조직명 | D6: 가상사업본부 가상사업단 가상1팀 | H6: 요청일자 | K6: 46023
A7: 요청사유 | D7: 2026년 최저임금 반영 | H7: 관리번호 | K7: 가상시 민원상담콜센터/2026년1월
A9: Ⅱ. 직무Group
A11: 직군명 | D11: TM직군
A12: 직무Group명 | D12: 가상시 민원상담콜센터 | H12: 직무Group정의 | K12: 고객상담
A14: Ⅲ. 직무 | R14: (단위 : 원, 명)
A15: 구분 | B15: 직무명 | E15: 직무정의 | H15: 직무/직책수당 | I15: 직무규정(소속) | R15: 비평가시 / (등급) | S15: 정원
A16: 조직장 | B16: 센터장 | E16: 센터장 업무 | H16: =Q67 -> 400000 | R16: X | S16: 1
B17: 팀장 | E17: 팀장 업무 | H17: =D67 -> 200000 | R17: X | S17: 1
B18: 교육/QAA | E18: 교육/QAA 업무 | H18: =E67 -> 150000 | R18: X | S18: 1
A19: 조직원 | B19: 상담사 | E19: 상담사 업무 | R19: X | S19: 20
A22: 계 | S22: =SUM(S16:S21) -> 23
A24: Ⅳ. 정원 | R24: (단위 : 명)
A25: 구분 | B25: 직급 | D25: 컨설턴트(일반) | I25: 컨설턴트(전문) | S25: 계
B26: 호봉 | D26: 수습 | E26: 상담1 | F26: 상담2 | G26: 상담3
A27: 정원 | D27: 3 | E27: 8 | F27: 6 | G27: 3 | S27: =SUM(D27:R27) -> 20
A28: 구분 | B28: 직급 | D28: Staff | P28: Leader | S28: 계
B29: 호봉 | D29: 상담팀장 | E29: 교육강사 | R29: 센터장
A30: 정원 | D30: 2 | E30: 1 | R30: 1 | S30: =SUM(D30:R30) -> 4
P31: 총계 | S31: =S27+S30 -> 24
A32: Ⅴ. 보수테이블 | R32: (단위 : 원, 명)
A33: 구분 | D33: 상담 | S33: 비고
D34: 수습 | E34: 상담1 | F34: 상담2 | G34: 상담3
A35: 기본급 | D35: =10320*209 -> 2156880 | E35: =10320*209 -> 2156880 | F35: =10320*209 -> 2156880 | G35: =10320*209 -> 2156880
A36: 직책수당
A37: 직무수당
A38: 근속수당 | F38: 20000 | G38: 40000
A39: 급식비 | D39: 100000 | E39: 100000 | F39: 100000 | G39: 100000
A40: 통근비
A41: 통상임금소계 | D41: =SUM(D35:D40) -> 2256880 | E41: =SUM(E35:E40) -> 2256880 | F41: =SUM(F35:F40) -> 2276880 | G41: =SUM(G35:G40) -> 2296880 | H41: =SUM(H35:H40) -> 0 | I41: =SUM(I35:I40) -> 0 | J41: =SUM(J35:J40) -> 0 | K41: =SUM(K35:K40) -> 0 | ... R41: =SUM(R35:R40) -> 0
A42: 업적수당 | C42: S | D42: 120000 | E42: 120000 | F42: 120000 | G42: 120000 | S42: 평가결과에 따름
C43: A | D43: 90000 | E43: 90000 | F43: 90000 | G43: 90000
C44: B | D44: 60000 | E44: 60000 | F44: 60000 | G44: 60000
C45: C. | D45: 30000 | E45: 30000 | F45: 30000 | G45: 30000
C46: D | D46: 10000 | E46: 10000 | F46: 10000 | G46: 10000
C47: E | D47: 0 | E47: 0 | F47: 0 | G47: 0 | H47: 0 | I47: 0 | J47: 0 | K47: 0 | L47: 0 | M47: 0 | N47: 0 | O47: 0 | P47: 0 | Q47: 0 | R47: 0
A48: 초과근무수당 | E48: =ROUNDUP(E53*2,-1) -> 32400 | F48: =ROUNDUP(F53*2,-1) -> 32690 | G48: =ROUNDUP(G53*2,-1) -> 32970 | S48: 2H
A49: 야간근로수당
...
